Workbook

Sheet 설정
A1: 항목 | B1: 값 (노란칸은 수정 가능) | C1: 기본값 근거·출처 | E1: ※ 위도·고도·풍속계높이·fetch를 바꾸면 계산과정이 자동 재계산됩니다.
A2: 위도 (°) | B2: 37.90262 | C2: 천문일사(Ra) 산정에 사용. [출처] 기상청 API 허브(stn_inf.php) 실시간 자동조회 실측값
A3: 고도 (m) | B3: 75.82 | C3: 기압 추정식·청천일사(Rso) 계산의 기준값(단, PM에 미치는 영향은 작음). [출처] 기상청 API 허브(stn_inf.php) 실시간 자동조회 실측값
A4: 풍속계 높이 (m) | B4: 10 | C4: 3개 메타값 중 PM에 가장 민감한 항목(지점마다 다름: 춘천 10·태백 16·수원 18.7m 등). [출처] 기상청 API 허브(stn_inf.php) 실시간 자동조회 실측값
A5: 증발접시 상풍거리 fetch (m) | B5: 100 | C5: FAO-56 Table 8 기본 가정값. 증발접시 주변이 녹지(잔디 등)이고 상풍(바람이 불어오는 방향) 노출거리 100m 기준 — 관측소 주변 환경 실사 전까지의 표준 근사치
A6: 지점번호 (참고용) | B6: 101 | C6: 실행 시 입력한 ASOS 지점번호. 관측지점 메타정보 출처: 기상청 API 허브(stn_inf.php) 실시간 자동조회 실측값
A7: 조회 시작일 (참고용) | B7: 20260101 | C7: 실행 시 입력한 조회기간 시작일. 계산식에는 사용되지 않고 원본 확인용으로만 표시
A8: 조회 종료일 (참고용) | B8: 20260913 | C8: 실행 시 입력한 조회기간 종료일. 계산식에는 사용되지 않고 원본 확인용으로만 표시
A9: [5] Kc 시나리오 — FAO-56 Table 12 (과수)
A10: 작물 | B10: 사과 — Apple | C10: crop_id=apple. 시나리오 4개 사용 가능. 작물을 바꾸려면 실행 시 --crop 인자를 사용(예: --crop cabbage). 라이브러리는 crops_library.csv, 사용자 수정은 crops_overrides.csv
A11: 시나리오 번호 (1~4) | B11: 3 | C11: 1=청경·서리 (0.45/0.95/0.70) | 2=청경·무서리 (0.60/0.95/0.75) | 3=초생재배·서리 (0.50/1.20/0.95, 한국 과수원 일반) | 4=초생재배·무서리 (0.80/1.20/0.85). 이 값을 바꾸면 아래 표값 3개와 최종 Kc가 자동 재계산됨.
A12: 표값 Kc_ini | B12: =CHOOSE(설정!$B$11,0.450,0.600,0.500,0.800) | C12: 선택된 시나리오의 초기 Kc 표값 (현지기상 보정 없음, 멀칭 보정만 적용)
A13: 표값 Kc_mid | B13: =CHOOSE(설정!$B$11,0.950,0.950,1.200,1.200) | C13: 선택된 시나리오의 생육중기 Kc 표값 (현지기상 보정 대상)
A14: 표값 Kc_end | B14: =CHOOSE(설정!$B$11,0.700,0.750,0.950,0.850) | C14: 선택된 시나리오의 생육후기 Kc 표값 (0.45 초과일 때만 현지기상 보정)
A15: [6] 생육단계 구분 — FAO-56 Table 11 (Deciduous Orchard, High Latitudes)
A16: 생육 시작일 (발아기/정식일) | B16: 46113 | C16: 사과 눈이 움직이기 시작하는 날 등, 작물의 생육 시작 시점(정식·파종·발아일). 지역·기후·품종에 따라 다름. 이 날짜부터 스테이지 카운트 시작.
A17: L_ini (초기, 일) | B17: 20 | C17: 발아 후 Kc가 Kc_ini에 머무는 기간. 작물 라이브러리 기본값(FAO-56 Table 11). 지역·품종 편차 클 때 실측 조정
A18: L_dev (발육, 일) | B18: 70 | C18: Kc가 Kc_ini→Kc_mid로 선형 증가하는 기간
A19: L_mid (중기, 일) | B19: 90 | C19: Kc가 Kc_mid에 머무는 기간(대개 생식 성장기~성숙 직전)
A20: L_late (후기, 일) | B20: 30 | C20: Kc가 Kc_mid→Kc_end로 선형 감소하는 기간(성숙~수확·낙엽)
A21: 총 생육기간 (일) | B21: =설정!$B$17+설정!$B$18+설정!$B$19+설정!$B$20 | C21: L_ini + L_dev + L_mid + L_late
A22: 생육중기 시작일 | B22: =설정!$B$16+설정!$B$17+설정!$B$18 | C22: 발아일 + L_ini + L_dev (현지기상 보정용 평균 산정 구간의 시작)
A23: 생육중기 종료일 | B23: =설정!$B$16+설정!$B$17+설정!$B$18+설정!$B$19-1 | C23: 생육중기 종료일(포함)
A24: 생육후기 종료일 (생육 종료) | B24: =설정!$B$16+설정!$B$21-1 | C24: 생육 종료일. 이 이후는 Kc=0 처리
A25: [7] Kc 현지기상 보정 — FAO-56 식(62) p.121, 식(65) p.125
A26: 생육중기 초목 수고 h (m) | B26: 3.2 | C26: 생육중기 캐노피 평균 높이. 작물 라이브러리 기본값. 현지기상 보정식의 (h/3)^0.3 항에 사용
A27: 중기 평균 u2 (m/s) | B27: 1.0136705 | C27: 조회기간 중 생육중기 구간의 실측 평균값(자동집계). 강원도원 워크북과 정합화 기준.
A28: 중기 평균 RHmin (%) | B28: 58.026316 | C28: 조회기간 중 생육중기 구간의 실측 평균값(자동집계, 최소상대습도 minRhm 기준).
A29: 후기 평균 u2 (m/s) | B29: 1.5 | C29: 생육후기 기간 실측 부족 → 기본값 1.5 사용
A30: 후기 평균 RHmin (%) | B30: 55 | C30: 생육후기 기간 실측 부족 → 기본값 55 사용
A31: 멀칭 Kc 보정계수 | B31: 1 | C31: 전면 비닐멀칭 시 Kc를 10~30% 낮춤(0.70~0.90). 없으면 1.00
A32: [5+7] 최종 적용 Kc (자동 계산)
A33: ★ 적용 Kc_ini | B33: =설정!$B$12*설정!$B$31 | C33: FAO-56 p.121: Kc_ini는 현지기상 보정 대상 아님. 멀칭 보정만 반영
A34: ★ 적용 Kc_mid (현지기상 보정 후) | B34: =(설정!$B$13+(0.04*(MEDIAN(1,설정!$B$27,6)-2)-0.004*(MEDIAN(20,설정!$B$28,80)-45))*(설정!$B$26/3)^0.3)*설정!$B$31 | C34: FAO-56 식(62): 현지기상(u2·RHmin) 보정. Kc_mid + [0.04(u2−2)−0.004(RHmin−45)](h/3)^0.3, 멀칭 보정 포함
A35: ★ 적용 Kc_end (현지기상 보정 후) | B35: =IF(설정!$B$14>0.45,(설정!$B$14+(0.04*(MEDIAN(1,설정!$B$29,6)-2)-0.004*(MEDIAN(20,설정!$B$30,80)-45))*(설정!$B$26/3)^0.3),설정!$B$14)*설정!$B$31 | C35: FAO-56 식(65): Kc_end>0.45인 경우만 현지기상 보정, 그 외는 표값 유지. 멀칭 보정 곱함
A36: [8] 토양·근권 파라미터 (물수지 계산용)
A37: 포장용수량 θFC (m³/m³) | B37: 0.22 | C37: FAO-56 Table 19, Loam(양토) 대표값. 토성에 따라 모래 0.10, 점토 0.36 범위
A38: 위조점 θWP (m³/m³) | B38: 0.1 | C38: FAO-56 Table 19, Loam(양토) 대표값. 모래 0.04, 점토 0.20 범위
A39: 근권심도 Zr (m) | B39: 1 | C39: FAO-56 Table 22. 사과 관수 스케줄링용 값. 천수답이면 큰 값 사용
A40: 토양수분고갈계수 p | B40: 0.5 | C40: FAO-56 Table 22. ETc≈5mm/d 기준. 고온건조 시 10-25% 감소, 저ETc 시 20% 증가
...

Sheet 원데이터
A1: 일자 | B1: 최고기온(℃) | C1: 최저기온(℃) | D1: 평균기온(℃) | E1: 평균습도(%) | F1: 최소습도(%) | G1: 평균풍속(m/s) | H1: 평균증기압(hPa) | I1: 평균이슬점(℃) | J1: 평균현지기압(hPa) | K1: 합계일사(MJ/m²) | L1: 합계일조(hr) | M1: 대형증발량(mm) | N1: 일강수량(mm)
A2: 46023 | B2: -2.2 | C2: -13.6 | D2: -8.5 | E2: 51.5 | F2: 24 | G2: 1.5 | H2: 1.5 | I2: -17.7 | J2: 1015.6 | K2: 10.35 | L2: 7.6 | M2: 1
A3: 46024 | B3: -2.4 | C3: -14.4 | D3: -9.1 | E3: 60.9 | F3: 29 | G3: 1.2 | H3: 1.8 | I3: -16 | J3: 1015.3 | K3: 10.53 | L3: 7.7 | M3: 0.9
A4: 46025 | B4: 0.6 | C4: -14.1 | D4: -7.4 | E4: 69.8 | F4: 36 | G4: 0.9 | H4: 2.4 | I4: -12.5 | J4: 1017.3 | K4: 10.13 | L4: 7.5 | M4: 0.9
A5: 46026 | B5: 5.2 | C5: -10.7 | D5: -3 | E5: 67.3 | F5: 31 | G5: 1.1 | H5: 3.1 | I5: -9 | J5: 1013.9 | K5: 9.45 | L5: 7.1 | M5: 1.2
A6: 46027 | B6: 3.4 | C6: -9.4 | D6: -4 | E6: 63.3 | F6: 26 | G6: 0.8 | H6: 2.7 | I6: -11.1 | J6: 1012.2 | K6: 10.34 | L6: 7.6 | M6: 1.2
A7: 46028 | B7: 1.9 | C7: -11.5 | D7: -4.5 | E7: 66.4 | F7: 32 | G7: 0.7 | H7: 2.8 | I7: -10.5 | J7: 1013.2 | K7: 8.43 | L7: 4.8 | M7: 0.8
A8: 46029 | B8: 4.2 | C8: -5.4 | D8: -1 | E8: 49.3 | F8: 18 | G8: 2.4 | H8: 2.8 | I8: -11.7 | J8: 1009.5 | K8: 10.17 | L8: 7.5 | M8: 1.8
A9: 46030 | B9: -0.7 | C9: -12.3 | D9: -6.7 | E9: 50.6 | F9: 21 | G9: 1.4 | H9: 1.7 | I9: -16.5 | J9: 1016.6 | K9: 10.62 | L9: 8 | M9: 1.2
A10: 46031 | B10: -0.1 | C10: -12.2 | D10: -4.4 | E10: 67.4 | F10: 47 | G10: 0.6 | H10: 3 | I10: -9.7 | J10: 1010.7 | K10: 3.64 | L10: 0.5 | M10: 0.4
A11: 46032 | B11: 5.4 | C11: -4.8 | D11: 0.6 | E11: 67.3 | F11: 29 | G11: 3.8 | H11: 4.3 | I11: -5.4 | J11: 999.8 | K11: 6.31 | L11: 2.9 | M11: 1.4 | N11: 4.6
A12: 46033 | B12: -3.7 | C12: -11.8 | D12: -7.5 | E12: 42 | F12: 19 | G12: 3.1 | H12: 1.4 | I12: -19.1 | J12: 1013.1 | K12: 10.61 | L12: 7.9 | M12: 1.3
A13: 46034 | B13: -3.9 | C13: -13.5 | D13: -7.7 | E13: 79.6 | F13: 62 | G13: 0.8 | H13: 2.9 | I13: -10.6 | J13: 1008.9 | K13: 3.73 | L13: 0 | M13: 0.4 | N13: 2.8
A14: 46035 | B14: -1.2 | C14: -12 | D14: -4.8 | E14: 49.6 | F14: 21 | G14: 2.7 | H14: 2.1 | I14: -14.9 | J14: 1007.2 | K14: 10.98 | L14: 7.9 | M14: 1.4 | N14: 1.1
A15: 46036 | B15: -1.2 | C15: -16 | D15: -7.1 | E15: 58.9 | F15: 32 | G15: 0.8 | H15: 2 | I15: -14.6 | J15: 1013.3 | K15: 7.42 | L15: 3.1 | M15: 0.7
A16: 46037 | B16: 4.5 | C16: -4.2 | D16: -1.1 | E16: 79.6 | F16: 46 | G16: 0.6 | H16: 4.5 | I16: -4.2 | J16: 1005.7 | K16: 4.89 | L16: 1.5 | M16: 0.5 | N16: 1.3
A17: 46038 | B17: 6.9 | C17: -5 | D17: 0.4 | E17: 86.4 | F17: 56 | G17: 0.4 | H17: 5.4 | I17: -1.7 | J17: 1009.3 | K17: 6.27 | L17: 3.7 | M17: 0.7
A18: 46039 | B18: 7.3 | C18: -5.2 | D18: -0.4 | E18: 69.9 | F18: 23 | G18: 0.9 | H18: 3.9 | I18: -6.3 | J18: 1011.1 | K18: 10.29 | L18: 7.2 | M18: 1.3
A19: 46040 | B19: 1.3 | C19: -6.5 | D19: -1.8 | E19: 75.8 | F19: 57 | G19: 0.8 | H19: 4.1 | I19: -5.6 | J19: 1012.8 | K19: 1.75 | L19: 0 | M19: 0.3 | N19: 0
A20: 46041 | B20: 1.7 | C20: -8.6 | D20: -2.3 | E20: 58.9 | F20: 28 | G20: 1.8 | H20: 3.3 | I20: -10.2 | J20: 1013.1 | K20: 6 | L20: 4.8 | M20: 1.1 | N20: 2.4
A21: 46042 | B21: -1.1 | C21: -12.6 | D21: -7.9 | E21: 50.9 | F21: 25 | G21: 1.6 | H21: 1.6 | I21: -16.9 | J21: 1017.5 | K21: 11.57 | L21: 8.1 | M21: 1.1
A22: 46043 | B22: -3.5 | C22: -16 | D22: -10 | E22: 56.3 | F22: 27 | G22: 1.7 | H22: 1.5 | I22: -17.9 | J22: 1016.6 | K22: 12.37 | L22: 8.2 | M22: 1.1
A23: 46044 | B23: -4.5 | C23: -17.3 | D23: -10.5 | E23: 53.8 | F23: 24 | G23: 2.1 | H23: 1.3 | I23: -19.2 | J23: 1017.3 | K23: 12.52 | L23: 8.2 | M23: 1.2
A24: 46045 | B24: -0.3 | C24: -16.8 | D24: -7.4 | E24: 59.1 | F24: 21 | G24: 1.4 | H24: 2 | I24: -15 | J24: 1015.5 | K24: 11.26 | L24: 7 | M24: 1.2 | N24: 0
A25: 46046 | B25: -0.8 | C25: -10.5 | D25: -5.1 | E25: 44.1 | F25: 17 | G25: 2.4 | H25: 1.7 | I25: -17 | J25: 1014.7 | K25: 12.35 | L25: 8.1 | M25: 1.6 | N25: 0
A26: 46047 | B26: -0.1 | C26: -14.7 | D26: -7.6 | E26: 49.6 | F26: 21 | G26: 1.3 | H26: 1.6 | I26: -17.2 | J26: 1019.6 | K26: 12.16 | L26: 8.1 | M26: 1.3
A27: 46048 | B27: -1 | C27: -12.6 | D27: -7.6 | E27: 65 | F27: 36 | G27: 0.9 | H27: 2.2 | I27: -13.4 | J27: 1016.8 | K27: 5.77 | L27: 1.5 | M27: 0.5
A28: 46049 | B28: 1.2 | C28: -12.8 | D28: -5.7 | E28: 57.4 | F28: 25 | G28: 1.6 | H28: 2.1 | I28: -14.1 | J28: 1015.1 | K28: 12.42 | L28: 8.2 | M28: 1.5
A29: 46050 | B29: 1.1 | C29: -14.2 | D29: -6.5 | E29: 49 | F29: 18 | G29: 1.6 | H29: 1.6 | I29: -17.1 | J29: 1018.5 | K29: 13.16 | L29: 8.4 | M29: 1.6
A30: 46051 | B30: 1.1 | C30: -14.1 | D30: -6.5 | E30: 45.5 | F30: 16 | G30: 1.7 | H30: 1.5 | I30: -18.1 | J30: 1019.2 | K30: 13.26 | L30: 8.4 | M30: 1.7
A31: 46052 | B31: -0.4 | C31: -13.7 | D31: -7.3 | E31: 49.3 | F31: 21 | G31: 1.2 | H31: 1.6 | I31: -17.2 | J31: 1020 | K31: 12.91 | L31: 8.4 | M31: 1.3
A32: 46053 | B32: 2.4 | C32: -13.9 | D32: -5.4 | E32: 50.8 | F32: 19 | G32: 1.7 | H32: 1.9 | I32: -15.5 | J32: 1017.7 | K32: 12.73 | L32: 8.4 | M32: 1.6
A33: 46054 | B33: 2.2 | C33: -12.2 | D33: -3.9 | E33: 57.1 | F33: 27 | G33: 1.6 | H33: 2.4 | I33: -12.4 | J33: 1015.5 | K33: 13.29 | L33: 8.6 | M33: 1.5 | N33: 0
A34: 46055 | B34: 2 | C34: -9.2 | D34: -3.9 | E34: 70.8 | F34: 35 | G34: 1.2 | H34: 3.1 | I34: -9 | J34: 1016.4 | K34: 10.58 | L34: 7 | M34: 1.2 | N34: 2.1
A35: 46056 | B35: 5.2 | C35: -12.3 | D35: -3.8 | E35: 65.6 | F35: 31 | G35: 1.4 | H35: 2.9 | I35: -10.1 | J35: 1018.8 | K35: 14.18 | L35: 8.9 | M35: 1.5
A36: 46057 | B36: 2.9 | C36: -7.8 | D36: -2.3 | E36: 79.9 | F36: 64 | G36: 0.6 | H36: 4.1 | I36: -5.4 | J36: 1013.2 | K36: 3.98 | L36: 0 | M36: 0.4
A37: 46058 | B37: 9.4 | C37: -4.4 | D37: 2.2 | E37: 75.8 | F37: 54 | G37: 1.6 | H37: 5.4 | I37: -1.9 | J37: 1008.2 | K37: 5.99 | L37: 1.9 | M37: 1.1 | N37: 0
A38: 46059 | B38: 1.2 | C38: -7.1 | D38: -3.4 | E38: 35.6 | F38: 18 | G38: 2.2 | H38: 1.7 | I38: -17.1 | J38: 1013.1 | K38: 13.86 | L38: 8.9 | M38: 1.8
A39: 46060 | B39: -1.8 | C39: -11.5 | D39: -7.1 | E39: 39.5 | F39: 17 | G39: 2.4 | H39: 1.4 | I39: -19.4 | J39: 1013.5 | K39: 14.61 | L39: 9.3 | M39: 1.7
A40: 46061 | B40: -2.3 | C40: -16.2 | D40: -8.8 | E40: 43.4 | F40: 20 | G40: 1.9 | H40: 1.3 | I40: -20 | J40: 1017.8 | K40: 14.4 | L40: 9.4 | M40: 1.4
...

Sheet 계산과정
A1: 일자 | B1: 연중일 DOY | C1: 평균기온 T(℃) | D1: e°(Tmax) | E1: e°(Tmin) | F1: 포화증기압 es(kPa) | G1: 실제증기압 ea(kPa) | H1: 기울기 Δ(kPa/℃) | I1: 기압 P(kPa) | J1: 건습계 γ(kPa/℃) | K1: 풍속 u₂(m/s) | L1: dr | M1: 적위 δ(rad) | N1: 일몰각 ωs(rad) | O1: 천문일사 Ra(MJ/m²) | P1: 청천일사 Rso(MJ/m²) | Q1: 일사 Rs(MJ/m²) | R1: 순단파 Rns(MJ/m²) | S1: 순장파 Rnl(MJ/m²) | T1: 순복사 Rn(MJ/m²) | U1: ★ ETo_PM(mm) | V1: 생육단계 | W1: 일별 Kc | X1: 증발접시계수 Kp | Y1: 대형증발량(mm) | Z1: ★ ETo_pan(mm) | AA1: ★ ETc_PM(mm) | AB1: ★ ETc_pan(mm)
A2: =원데이터!A2 | B2: =원데이터!A2-DATE(YEAR(원데이터!A2),1,1)+1 | C2: =(원데이터!B2+원데이터!C2)/2 | D2: =0.6108*EXP(17.27*원데이터!B2/(원데이터!B2+237.3)) | E2: =0.6108*EXP(17.27*원데이터!C2/(원데이터!C2+237.3)) | F2: =(D2+E2)/2 | G2: =IF(원데이터!H2<>"",원데이터!H2/10,IF(원데이터!I2<>"",0.6108*EXP(17.27*원데이터!I2/(원데이터!I2+237.3)),원데이터!E2/100*F2)) | H2: =4098*(0.6108*EXP(17.27*C2/(C2+237.3)))/(C2+237.3)^2 | I2: =IF(원데이터!J2<>"",원데이터!J2/10,101.3*((293-0.0065*설정!$B$3)/293)^5.26) | J2: =0.000665*I2 | K2: =원데이터!G2*4.87/LN(67.8*설정!$B$4-5.42) | L2: =1+0.033*COS(2*PI()*B2/365) | M2: =0.409*SIN(2*PI()*B2/365-1.39) | N2: =ACOS(-TAN(RADIANS(설정!$B$2))*TAN(M2)) | O2: =(24*60/PI())*0.082*L2*(N2*SIN(RADIANS(설정!$B$2))*SIN(M2)+COS(RADIANS(설정!$B$2))*COS(M2)*SIN(N2)) | P2: =(0.75+0.00002*설정!$B$3)*O2 | Q2: =IF(원데이터!K2<>"",원데이터!K2,(0.25+0.5*원데이터!L2/(24/PI()*N2))*O2) | R2: =0.77*Q2 | S2: =0.000000004903*(((원데이터!B2+273.16)^4+(원데이터!C2+273.16)^4)/2)*(0.34-0.14*SQRT(G2))*(1.35*MIN(Q2/P2,1)-0.35) | T2: =R2-S2 | U2: =(0.408*H2*T2+J2*(900/(C2+273))*K2*(F2-G2))/(H2+J2*(1+0.34*K2)) | V2: =IF(원데이터!A2-설정!$B$16<0,"발아전",IF(원데이터!A2-설정!$B$16<설정!$B$17,"초기",IF(원데이터!A2-설정!$B$16<설정!$B$17+설정!$B$18,"발육",IF(원데이터!A2-설정!$B$16<설정!$B$17+설정!$B$18+설정!$B$19,"중기",IF(원데이터!A2-설정!$B$16<설정!$B$17+설정!$B$18+설정!$B$19+설정!$B$20,"후기","후기이후"))))) | W2: =IF(원데이터!A2-설정!$B$16<0,0,IF(원데이터!A2-설정!$B$16<설정!$B$17,설정!$B$33,IF(원데이터!A2-설정!$B$16<설정!$B$17+설정!$B$18,설정!$B$33+(설정!$B$34-설정!$B$33)*(원데이터!A2-설정!$B$16-설정!$B$17+1)/설정!$B$18,IF(원데이터!A2-설정!$B$16<설정!$B$17+설정!$B$18+설정!$B$19,설정!$B$34,IF(원데이터!A2-설정!$B$16<설정!$B$17+설정!$B$18+설정!$B$19+설정!$B$20,설정!$B$34+(설정!$B$35-설정!$B$34)*(원데이터!A2-설정!$B$16-설정!$B$17-설정!$B$18-설정!$B$19+1)/설정!$B$20,0))))) | X2: =0.108-0.0286*K2+0.0422*LN(설정!$B$5)+0.1434*LN(원데이터!E2)-0.000631*LN(설정!$B$5)^2*LN(원데이터!E2) | Y2: =원데이터!M2 | Z2: =X2*Y2 | AA2: =U2*W2 | AB2: =Z2*W2
A3: =원데이터!A3 | B3: =원데이터!A3-DATE(YEAR(원데이터!A3),1,1)+1 | C3: =(원데이터!B3+원데이터!C3)/2 | D3: =0.6108*EXP(17.27*원데이터!B3/(원데이터!B3+237.3)) | E3: =0.6108*EXP(17.27*원데이터!C3/(원데이터!C3+237.3)) | F3: =(D3+E3)/2 | G3: =IF(원데이터!H3<>"",원데이터!H3/10,IF(원데이터!I3<>"",0.6108*EXP(17.27*원데이터!I3/(원데이터!I3+237.3)),원데이터!E3/100*F3)) | H3: =4098*(0.6108*EXP(17.27*C3/(C3+237.3)))/(C3+237.3)^2 | I3: =IF(원데이터!J3<>"",원데이터!J3/10,101.3*((293-0.0065*설정!$B$3)/293)^5.26) | J3: =0.000665*I3 | K3: =원데이터!G3*4.87/LN(67.8*설정!$B$4-5.42) | L3: =1+0.033*COS(2*PI()*B3/365) | M3: =0.409*SIN(2*PI()*B3/365-1.39) | N3: =ACOS(-TAN(RADIANS(설정!$B$2))*TAN(M3)) | O3: =(24*60/PI())*0.082*L3*(N3*SIN(RADIANS(설정!$B$2))*SIN(M3)+COS(RADIANS(설정!$B$2))*COS(M3)*SIN(N3)) | P3: =(0.75+0.00002*설정!$B$3)*O3 | Q3: =IF(원데이터!K3<>"",원데이터!K3,(0.25+0.5*원데이터!L3/(24/PI()*N3))*O3) | R3: =0.77*Q3 | S3: =0.000000004903*(((원데이터!B3+273.16)^4+(원데이터!C3+273.16)^4)/2)*(0.34-0.14*SQRT(G3))*(1.35*MIN(Q3/P3,1)-0.35) | T3: =R3-S3 | U3: =(0.408*H3*T3+J3*(900/(C3+273))*K3*(F3-G3))/(H3+J3*(1+0.34*K3)) | V3: =IF(원데이터!A3-설정!$B$16<0,"발아전",IF(원데이터!A3-설정!$B$16<설정!$B$17,"초기",IF(원데이터!A3-설정!$B$16<설정!$B$17+설정!$B$18,"발육",IF(원데이터!A3-설정!$B$16<설정!$B$17+설정!$B$18+설정!$B$19,"중기",IF(원데이터!A3-설정!$B$16<설정!$B$17+설정!$B$18+설정!$B$19+설정!$B$20,"후기","후기이후"))))) | W3: =IF(원데이터!A3-설정!$B$16<0,0,IF(원데이터!A3-설정!$B$16<설정!$B$17,설정!$B$33,IF(원데이터!A3-설정!$B$16<설정!$B$17+설정!$B$18,설정!$B$33+(설정!$B$34-설정!$B$33)*(원데이터!A3-설정!$B$16-설정!$B$17+1)/설정!$B$18,IF(원데이터!A3-설정!$B$16<설정!$B$17+설정!$B$18+설정!$B$19,설정!$B$34,IF(원데이터!A3-설정!$B$16<설정!$B$17+설정!$B$18+설정!$B$19+설정!$B$20,설정!$B$34+(설정!$B$35-설정!$B$34)*(원데이터!A3-설정!$B$16-설정!$B$17-설정!$B$18-설정!$B$19+1)/설정!$B$20,0))))) | X3: =0.108-0.0286*K3+0.0422*LN(설정!$B$5)+0.1434*LN(원데이터!E3)-0.000631*LN(설정!$B$5)^2*LN(원데이터!E3) | Y3: =원데이터!M3 | Z3: =X3*Y3 | AA3: =U3*W3 | AB3: =Z3*W3
A4: =원데이터!A4 | B4: =원데이터!A4-DATE(YEAR(원데이터!A4),1,1)+1 | C4: =(원데이터!B4+원데이터!C4)/2 | D4: =0.6108*EXP(17.27*원데이터!B4/(원데이터!B4+237.3)) | E4: =0.6108*EXP(17.27*원데이터!C4/(원데이터!C4+237.3)) | F4: =(D4+E4)/2 | G4: =IF(원데이터!H4<>"",원데이터!H4/10,IF(원데이터!I4<>"",0.6108*EXP(17.27*원데이터!I4/(원데이터!I4+237.3)),원데이터!E4/100*F4)) | H4: =4098*(0.6108*EXP(17.27*C4/(C4+237.3)))/(C4+237.3)^2 | I4: =IF(원데이터!J4<>"",원데이터!J4/10,101.3*((293-0.0065*설정!$B$3)/293)^5.26) | J4: =0.000665*I4 | K4: =원데이터!G4*4.87/LN(67.8*설정!$B$4-5.42) | L4: =1+0.033*COS(2*PI()*B4/365) | M4: =0.409*SIN(2*PI()*B4/365-1.39) | N4: =ACOS(-TAN(RADIANS(설정!$B$2))*TAN(M4)) | O4: =(24*60/PI())*0.082*L4*(N4*SIN(RADIANS(설정!$B$2))*SIN(M4)+COS(RADIANS(설정!$B$2))*COS(M4)*SIN(N4)) | P4: =(0.75+0.00002*설정!$B$3)*O4 | Q4: =IF(원데이터!K4<>"",원데이터!K4,(0.25+0.5*원데이터!L4/(24/PI()*N4))*O4) | R4: =0.77*Q4 | S4: =0.000000004903*(((원데이터!B4+273.16)^4+(원데이터!C4+273.16)^4)/2)*(0.34-0.14*SQRT(G4))*(1.35*MIN(Q4/P4,1)-0.35) | T4: =R4-S4 | U4: =(0.408*H4*T4+J4*(900/(C4+273))*K4*(F4-G4))/(H4+J4*(1+0.34*K4)) | V4: =IF(원데이터!A4-설정!$B$16<0,"발아전",IF(원데이터!A4-설정!$B$16<설정!$B$17,"초기",IF(원데이터!A4-설정!$B$16<설정!$B$17+설정!$B$18,"발육",IF(원데이터!A4-설정!$B$16<설정!$B$17+설정!$B$18+설정!$B$19,"중기",IF(원데이터!A4-설정!$B$16<설정!$B$17+설정!$B$18+설정!$B$19+설정!$B$20,"후기","후기이후"))))) | W4: =IF(원데이터!A4-설정!$B$16<0,0,IF(원데이터!A4-설정!$B$16<설정!$B$17,설정!$B$33,IF(원데이터!A4-설정!$B$16<설정!$B$17+설정!$B$18,설정!$B$33+(설정!$B$34-설정!$B$33)*(원데이터!A4-설정!$B$16-설정!$B$17+1)/설정!$B$18,IF(원데이터!A4-설정!$B$16<설정!$B$17+설정!$B$18+설정!$B$19,설정!$B$34,IF(원데이터!A4-설정!$B$16<설정!$B$17+설정!$B$18+설정!$B$19+설정!$B$20,설정!$B$34+(설정!$B$35-설정!$B$34)*(원데이터!A4-설정!$B$16-설정!$B$17-설정!$B$18-설정!$B$19+1)/설정!$B$20,0))))) | X4: =0.108-0.0286*K4+0.0422*LN(설정!$B$5)+0.1434*LN(원데이터!E4)-0.000631*LN(설정!$B$5)^2*LN(원데이터!E4) | Y4: =원데이터!M4 | Z4: =X4*Y4 | AA4: =U4*W4 | AB4: =Z4*W4
A5: =원데이터!A5 | B5: =원데이터!A5-DATE(YEAR(원데이터!A5),1,1)+1 | C5: =(원데이터!B5+원데이터!C5)/2 | D5: =0.6108*EXP(17.27*원데이터!B5/(원데이터!B5+237.3)) | E5: =0.6108*EXP(17.27*원데이터!C5/(원데이터!C5+237.3)) | F5: =(D5+E5)/2 | G5: =IF(원데이터!H5<>"",원데이터!H5/10,IF(원데이터!I5<>"",0.6108*EXP(17.27*원데이터!I5/(원데이터!I5+237.3)),원데이터!E5/100*F5)) | H5: =4098*(0.6108*EXP(17.27*C5/(C5+237.3)))/(C5+237.3)^2 | I5: =IF(원데이터!J5<>"",원데이터!J5/10,101.3*((293-0.0065*설정!$B$3)/293)^5.26) | J5: =0.000665*I5 | K5: =원데이터!G5*4.87/LN(67.8*설정!$B$4-5.42) | L5: =1+0.033*COS(2*PI()*B5/365) | M5: =0.409*SIN(2*PI()*B5/365-1.39) | N5: =ACOS(-TAN(RADIANS(설정!$B$2))*TAN(M5)) | O5: =(24*60/PI())*0.082*L5*(N5*SIN(RADIANS(설정!$B$2))*SIN(M5)+COS(RADIANS(설정!$B$2))*COS(M5)*SIN(N5)) | P5: =(0.75+0.00002*설정!$B$3)*O5 | Q5: =IF(원데이터!K5<>"",원데이터!K5,(0.25+0.5*원데이터!L5/(24/PI()*N5))*O5) | R5: =0.77*Q5 | S5: =0.000000004903*(((원데이터!B5+273.16)^4+(원데이터!C5+273.16)^4)/2)*(0.34-0.14*SQRT(G5))*(1.35*MIN(Q5/P5,1)-0.35) | T5: =R5-S5 | U5: =(0.408*H5*T5+J5*(900/(C5+273))*K5*(F5-G5))/(H5+J5*(1+0.34*K5)) | V5: =IF(원데이터!A5-설정!$B$16<0,"발아전",IF(원데이터!A5-설정!$B$16<설정!$B$17,"초기",IF(원데이터!A5-설정!$B$16<설정!$B$17+설정!$B$18,"발육",IF(원데이터!A5-설정!$B$16<설정!$B$17+설정!$B$18+설정!$B$19,"중기",IF(원데이터!A5-설정!$B$16<설정!$B$17+설정!$B$18+설정!$B$19+설정!$B$20,"후기","후기이후"))))) | W5: =IF(원데이터!A5-설정!$B$16<0,0,IF(원데이터!A5-설정!$B$16<설정!$B$17,설정!$B$33,IF(원데이터!A5-설정!$B$16<설정!$B$17+설정!$B$18,설정!$B$33+(설정!$B$34-설정!$B$33)*(원데이터!A5-설정!$B$16-설정!$B$17+1)/설정!$B$18,IF(원데이터!A5-설정!$B$16<설정!$B$17+설정!$B$18+설정!$B$19,설정!$B$34,IF(원데이터!A5-설정!$B$16<설정!$B$17+설정!$B$18+설정!$B$19+설정!$B$20,설정!$B$34+(설정!$B$35-설정!$B$34)*(원데이터!A5-설정!$B$16-설정!$B$17-설정!$B$18-설정!$B$19+1)/설정!$B$20,0))))) | X5: =0.108-0.0286*K5+0.0422*LN(설정!$B$5)+0.1434*LN(원데이터!E5)-0.000631*LN(설정!$B$5)^2*LN(원데이터!E5) | Y5: =원데이터!M5 | Z5: =X5*Y5 | AA5: =U5*W5 | AB5: =Z5*W5
A6: =원데이터!A6 | B6: =원데이터!A6-DATE(YEAR(원데이터!A6),1,1)+1 | C6: =(원데이터!B6+원데이터!C6)/2 | D6: =0.6108*EXP(17.27*원데이터!B6/(원데이터!B6+237.3)) | E6: =0.6108*EXP(17.27*원데이터!C6/(원데이터!C6+237.3)) | F6: =(D6+E6)/2 | G6: =IF(원데이터!H6<>"",원데이터!H6/10,IF(원데이터!I6<>"",0.6108*EXP(17.27*원데이터!I6/(원데이터!I6+237.3)),원데이터!E6/100*F6)) | H6: =4098*(0.6108*EXP(17.27*C6/(C6+237.3)))/(C6+237.3)^2 | I6: =IF(원데이터!J6<>"",원데이터!J6/10,101.3*((293-0.0065*설정!$B$3)/293)^5.26) | J6: =0.000665*I6 | K6: =원데이터!G6*4.87/LN(67.8*설정!$B$4-5.42) | L6: =1+0.033*COS(2*PI()*B6/365) | M6: =0.409*SIN(2*PI()*B6/365-1.39) | N6: =ACOS(-TAN(RADIANS(설정!$B$2))*TAN(M6)) | O6: =(24*60/PI())*0.082*L6*(N6*SIN(RADIANS(설정!$B$2))*SIN(M6)+COS(RADIANS(설정!$B$2))*COS(M6)*SIN(N6)) | P6: =(0.75+0.00002*설정!$B$3)*O6 | Q6: =IF(원데이터!K6<>"",원데이터!K6,(0.25+0.5*원데이터!L6/(24/PI()*N6))*O6) | R6: =0.77*Q6 | S6: =0.000000004903*(((원데이터!B6+273.16)^4+(원데이터!C6+273.16)^4)/2)*(0.34-0.14*SQRT(G6))*(1.35*MIN(Q6/P6,1)-0.35) | T6: =R6-S6 | U6: =(0.408*H6*T6+J6*(900/(C6+273))*K6*(F6-G6))/(H6+J6*(1+0.34*K6)) | V6: =IF(원데이터!A6-설정!$B$16<0,"발아전",IF(원데이터!A6-설정!$B$16<설정!$B$17,"초기",IF(원데이터!A6-설정!$B$16<설정!$B$17+설정!$B$18,"발육",IF(원데이터!A6-설정!$B$16<설정!$B$17+설정!$B$18+설정!$B$19,"중기",IF(원데이터!A6-설정!$B$16<설정!$B$17+설정!$B$18+설정!$B$19+설정!$B$20,"후기","후기이후"))))) | W6: =IF(원데이터!A6-설정!$B$16<0,0,IF(원데이터!A6-설정!$B$16<설정!$B$17,설정!$B$33,IF(원데이터!A6-설정!$B$16<설정!$B$17+설정!$B$18,설정!$B$33+(설정!$B$34-설정!$B$33)*(원데이터!A6-설정!$B$16-설정!$B$17+1)/설정!$B$18,IF(원데이터!A6-설정!$B$16<설정!$B$17+설정!$B$18+설정!$B$19,설정!$B$34,IF(원데이터!A6-설정!$B$16<설정!$B$17+설정!$B$18+설정!$B$19+설정!$B$20,설정!$B$34+(설정!$B$35-설정!$B$34)*(원데이터!A6-설정!$B$16-설정!$B$17-설정!$B$18-설정!$B$19+1)/설정!$B$20,0))))) | X6: =0.108-0.0286*K6+0.0422*LN(설정!$B$5)+0.1434*LN(원데이터!E6)-0.000631*LN(설정!$B$5)^2*LN(원데이터!E6) | Y6: =원데이터!M6 | Z6: =X6*Y6 | AA6: =U6*W6 | AB6: =Z6*W6
A7: =원데이터!A7 | B7: =원데이터!A7-DATE(YEAR(원데이터!A7),1,1)+1 | C7: =(원데이터!B7+원데이터!C7)/2 | D7: =0.6108*EXP(17.27*원데이터!B7/(원데이터!B7+237.3)) | E7: =0.6108*EXP(17.27*원데이터!C7/(원데이터!C7+237.3)) | F7: =(D7+E7)/2 | G7: =IF(원데이터!H7<>"",원데이터!H7/10,IF(원데이터!I7<>"",0.6108*EXP(17.27*원데이터!I7/(원데이터!I7+237.3)),원데이터!E7/100*F7)) | H7: =4098*(0.6108*EXP(17.27*C7/(C7+237.3)))/(C7+237.3)^2 | I7: =IF(원데이터!J7<>"",원데이터!J7/10,101.3*((293-0.0065*설정!$B$3)/293)^5.26) | J7: =0.000665*I7 | K7: =원데이터!G7*4.87/LN(67.8*설정!$B$4-5.42) | L7: =1+0.033*COS(2*PI()*B7/365) | M7: =0.409*SIN(2*PI()*B7/365-1.39) | N7: =ACOS(-TAN(RADIANS(설정!$B$2))*TAN(M7)) | O7: =(24*60/PI())*0.082*L7*(N7*SIN(RADIANS(설정!$B$2))*SIN(M7)+COS(RADIANS(설정!$B$2))*COS(M7)*SIN(N7)) | P7: =(0.75+0.00002*설정!$B$3)*O7 | Q7: =IF(원데이터!K7<>"",원데이터!K7,(0.25+0.5*원데이터!L7/(24/PI()*N7))*O7) | R7: =0.77*Q7 | S7: =0.000000004903*(((원데이터!B7+273.16)^4+(원데이터!C7+273.16)^4)/2)*(0.34-0.14*SQRT(G7))*(1.35*MIN(Q7/P7,1)-0.35) | T7: =R7-S7 | U7: =(0.408*H7*T7+J7*(900/(C7+273))*K7*(F7-G7))/(H7+J7*(1+0.34*K7)) | V7: =IF(원데이터!A7-설정!$B$16<0,"발아전",IF(원데이터!A7-설정!$B$16<설정!$B$17,"초기",IF(원데이터!A7-설정!$B$16<설정!$B$17+설정!$B$18,"발육",IF(원데이터!A7-설정!$B$16<설정!$B$17+설정!$B$18+설정!$B$19,"중기",IF(원데이터!A7-설정!$B$16<설정!$B$17+설정!$B$18+설정!$B$19+설정!$B$20,"후기","후기이후"))))) | W7: =IF(원데이터!A7-설정!$B$16<0,0,IF(원데이터!A7-설정!$B$16<설정!$B$17,설정!$B$33,IF(원데이터!A7-설정!$B$16<설정!$B$17+설정!$B$18,설정!$B$33+(설정!$B$34-설정!$B$33)*(원데이터!A7-설정!$B$16-설정!$B$17+1)/설정!$B$18,IF(원데이터!A7-설정!$B$16<설정!$B$17+설정!$B$18+설정!$B$19,설정!$B$34,IF(원데이터!A7-설정!$B$16<설정!$B$17+설정!$B$18+설정!$B$19+설정!$B$20,설정!$B$34+(설정!$B$35-설정!$B$34)*(원데이터!A7-설정!$B$16-설정!$B$17-설정!$B$18-설정!$B$19+1)/설정!$B$20,0))))) | X7: =0.108-0.0286*K7+0.0422*LN(설정!$B$5)+0.1434*LN(원데이터!E7)-0.000631*LN(설정!$B$5)^2*LN(원데이터!E7) | Y7: =원데이터!M7 | Z7: =X7*Y7 | AA7: =U7*W7 | AB7: =Z7*W7
A8: =원데이터!A8 | B8: =원데이터!A8-DATE(YEAR(원데이터!A8),1,1)+1 | C8: =(원데이터!B8+원데이터!C8)/2 | D8: =0.6108*EXP(17.27*원데이터!B8/(원데이터!B8+237.3)) | E8: =0.6108*EXP(17.27*원데이터!C8/(원데이터!C8+237.3)) | F8: =(D8+E8)/2 | G8: =IF(원데이터!H8<>"",원데이터!H8/10,IF(원데이터!I8<>"",0.6108*EXP(17.27*원데이터!I8/(원데이터!I8+237.3)),원데이터!E8/100*F8)) | H8: =4098*(0.6108*EXP(17.27*C8/(C8+237.3)))/(C8+237.3)^2 | I8: =IF(원데이터!J8<>"",원데이터!J8/10,101.3*((293-0.0065*설정!$B$3)/293)^5.26) | J8: =0.000665*I8 | K8: =원데이터!G8*4.87/LN(67.8*설정!$B$4-5.42) | L8: =1+0.033*COS(2*PI()*B8/365) | M8: =0.409*SIN(2*PI()*B8/365-1.39) | N8: =ACOS(-TAN(RADIANS(설정!$B$2))*TAN(M8)) | O8: =(24*60/PI())*0.082*L8*(N8*SIN(RADIANS(설정!$B$2))*SIN(M8)+COS(RADIANS(설정!$B$2))*COS(M8)*SIN(N8)) | P8: =(0.75+0.00002*설정!$B$3)*O8 | Q8: =IF(원데이터!K8<>"",원데이터!K8,(0.25+0.5*원데이터!L8/(24/PI()*N8))*O8) | R8: =0.77*Q8 | S8: =0.000000004903*(((원데이터!B8+273.16)^4+(원데이터!C8+273.16)^4)/2)*(0.34-0.14*SQRT(G8))*(1.35*MIN(Q8/P8,1)-0.35) | T8: =R8-S8 | U8: =(0.408*H8*T8+J8*(900/(C8+273))*K8*(F8-G8))/(H8+J8*(1+0.34*K8)) | V8: =IF(원데이터!A8-설정!$B$16<0,"발아전",IF(원데이터!A8-설정!$B$16<설정!$B$17,"초기",IF(원데이터!A8-설정!$B$16<설정!$B$17+설정!$B$18,"발육",IF(원데이터!A8-설정!$B$16<설정!$B$17+설정!$B$18+설정!$B$19,"중기",IF(원데이터!A8-설정!$B$16<설정!$B$17+설정!$B$18+설정!$B$19+설정!$B$20,"후기","후기이후"))))) | W8: =IF(원데이터!A8-설정!$B$16<0,0,IF(원데이터!A8-설정!$B$16<설정!$B$17,설정!$B$33,IF(원데이터!A8-설정!$B$16<설정!$B$17+설정!$B$18,설정!$B$33+(설정!$B$34-설정!$B$33)*(원데이터!A8-설정!$B$16-설정!$B$17+1)/설정!$B$18,IF(원데이터!A8-설정!$B$16<설정!$B$17+설정!$B$18+설정!$B$19,설정!$B$34,IF(원데이터!A8-설정!$B$16<설정!$B$17+설정!$B$18+설정!$B$19+설정!$B$20,설정!$B$34+(설정!$B$35-설정!$B$34)*(원데이터!A8-설정!$B$16-설정!$B$17-설정!$B$18-설정!$B$19+1)/설정!$B$20,0))))) | X8: =0.108-0.0286*K8+0.0422*LN(설정!$B$5)+0.1434*LN(원데이터!E8)-0.000631*LN(설정!$B$5)^2*LN(원데이터!E8) | Y8: =원데이터!M8 | Z8: =X8*Y8 | AA8: =U8*W8 | AB8: =Z8*W8
A9: =원데이터!A9 | B9: =원데이터!A9-DATE(YEAR(원데이터!A9),1,1)+1 | C9: =(원데이터!B9+원데이터!C9)/2 | D9: =0.6108*EXP(17.27*원데이터!B9/(원데이터!B9+237.3)) | E9: =0.6108*EXP(17.27*원데이터!C9/(원데이터!C9+237.3)) | F9: =(D9+E9)/2 | G9: =IF(원데이터!H9<>"",원데이터!H9/10,IF(원데이터!I9<>"",0.6108*EXP(17.27*원데이터!I9/(원데이터!I9+237.3)),원데이터!E9/100*F9)) | H9: =4098*(0.6108*EXP(17.27*C9/(C9+237.3)))/(C9+237.3)^2 | I9: =IF(원데이터!J9<>"",원데이터!J9/10,101.3*((293-0.0065*설정!$B$3)/293)^5.26) | J9: =0.000665*I9 | K9: =원데이터!G9*4.87/LN(67.8*설정!$B$4-5.42) | L9: =1+0.033*COS(2*PI()*B9/365) | M9: =0.409*SIN(2*PI()*B9/365-1.39) | N9: =ACOS(-TAN(RADIANS(설정!$B$2))*TAN(M9)) | O9: =(24*60/PI())*0.082*L9*(N9*SIN(RADIANS(설정!$B$2))*SIN(M9)+COS(RADIANS(설정!$B$2))*COS(M9)*SIN(N9)) | P9: =(0.75+0.00002*설정!$B$3)*O9 | Q9: =IF(원데이터!K9<>"",원데이터!K9,(0.25+0.5*원데이터!L9/(24/PI()*N9))*O9) | R9: =0.77*Q9 | S9: =0.000000004903*(((원데이터!B9+273.16)^4+(원데이터!C9+273.16)^4)/2)*(0.34-0.14*SQRT(G9))*(1.35*MIN(Q9/P9,1)-0.35) | T9: =R9-S9 | U9: =(0.408*H9*T9+J9*(900/(C9+273))*K9*(F9-G9))/(H9+J9*(1+0.34*K9)) | V9: =IF(원데이터!A9-설정!$B$16<0,"발아전",IF(원데이터!A9-설정!$B$16<설정!$B$17,"초기",IF(원데이터!A9-설정!$B$16<설정!$B$17+설정!$B$18,"발육",IF(원데이터!A9-설정!$B$16<설정!$B$17+설정!$B$18+설정!$B$19,"중기",IF(원데이터!A9-설정!$B$16<설정!$B$17+설정!$B$18+설정!$B$19+설정!$B$20,"후기","후기이후"))))) | W9: =IF(원데이터!A9-설정!$B$16<0,0,IF(원데이터!A9-설정!$B$16<설정!$B$17,설정!$B$33,IF(원데이터!A9-설정!$B$16<설정!$B$17+설정!$B$18,설정!$B$33+(설정!$B$34-설정!$B$33)*(원데이터!A9-설정!$B$16-설정!$B$17+1)/설정!$B$18,IF(원데이터!A9-설정!$B$16<설정!$B$17+설정!$B$18+설정!$B$19,설정!$B$34,IF(원데이터!A9-설정!$B$16<설정!$B$17+설정!$B$18+설정!$B$19+설정!$B$20,설정!$B$34+(설정!$B$35-설정!$B$34)*(원데이터!A9-설정!$B$16-설정!$B$17-설정!$B$18-설정!$B$19+1)/설정!$B$20,0))))) | X9: =0.108-0.0286*K9+0.0422*LN(설정!$B$5)+0.1434*LN(원데이터!E9)-0.000631*LN(설정!$B$5)^2*LN(원데이터!E9) | Y9: =원데이터!M9 | Z9: =X9*Y9 | AA9: =U9*W9 | AB9: =Z9*W9
A10: =원데이터!A10 | B10: =원데이터!A10-DATE(YEAR(원데이터!A10),1,1)+1 | C10: =(원데이터!B10+원데이터!C10)/2 | D10: =0.6108*EXP(17.27*원데이터!B10/(원데이터!B10+237.3)) | E10: =0.6108*EXP(17.27*원데이터!C10/(원데이터!C10+237.3)) | F10: =(D10+E10)/2 | G10: =IF(원데이터!H10<>"",원데이터!H10/10,IF(원데이터!I10<>"",0.6108*EXP(17.27*원데이터!I10/(원데이터!I10+237.3)),원데이터!E10/100*F10)) | H10: =4098*(0.6108*EXP(17.27*C10/(C10+237.3)))/(C10+237.3)^2 | I10: =IF(원데이터!J10<>"",원데이터!J10/10,101.3*((293-0.0065*설정!$B$3)/293)^5.26) | J10: =0.000665*I10 | K10: =원데이터!G10*4.87/LN(67.8*설정!$B$4-5.42) | L10: =1+0.033*COS(2*PI()*B10/365) | M10: =0.409*SIN(2*PI()*B10/365-1.39) | N10: =ACOS(-TAN(RADIANS(설정!$B$2))*TAN(M10)) | O10: =(24*60/PI())*0.082*L10*(N10*SIN(RADIANS(설정!$B$2))*SIN(M10)+COS(RADIANS(설정!$B$2))*COS(M10)*SIN(N10)) | P10: =(0.75+0.00002*설정!$B$3)*O10 | Q10: =IF(원데이터!K10<>"",원데이터!K10,(0.25+0.5*원데이터!L10/(24/PI()*N10))*O10) | R10: =0.77*Q10 | S10: =0.000000004903*(((원데이터!B10+273.16)^4+(원데이터!C10+273.16)^4)/2)*(0.34-0.14*SQRT(G10))*(1.35*MIN(Q10/P10,1)-0.35) | T10: =R10-S10 | U10: =(0.408*H10*T10+J10*(900/(C10+273))*K10*(F10-G10))/(H10+J10*(1+0.34*K10)) | V10: =IF(원데이터!A10-설정!$B$16<0,"발아전",IF(원데이터!A10-설정!$B$16<설정!$B$17,"초기",IF(원데이터!A10-설정!$B$16<설정!$B$17+설정!$B$18,"발육",IF(원데이터!A10-설정!$B$16<설정!$B$17+설정!$B$18+설정!$B$19,"중기",IF(원데이터!A10-설정!$B$16<설정!$B$17+설정!$B$18+설정!$B$19+설정!$B$20,"후기","후기이후"))))) | W10: =IF(원데이터!A10-설정!$B$16<0,0,IF(원데이터!A10-설정!$B$16<설정!$B$17,설정!$B$33,IF(원데이터!A10-설정!$B$16<설정!$B$17+설정!$B$18,설정!$B$33+(설정!$B$34-설정!$B$33)*(원데이터!A10-설정!$B$16-설정!$B$17+1)/설정!$B$18,IF(원데이터!A10-설정!$B$16<설정!$B$17+설정!$B$18+설정!$B$19,설정!$B$34,IF(원데이터!A10-설정!$B$16<설정!$B$17+설정!$B$18+설정!$B$19+설정!$B$20,설정!$B$34+(설정!$B$35-설정!$B$34)*(원데이터!A10-설정!$B$16-설정!$B$17-설정!$B$18-설정!$B$19+1)/설정!$B$20,0))))) | X10: =0.108-0.0286*K10+0.0422*LN(설정!$B$5)+0.1434*LN(원데이터!E10)-0.000631*LN(설정!$B$5)^2*LN(원데이터!E10) | Y10: =원데이터!M10 | Z10: =X10*Y10 | AA10: =U10*W10 | AB10: =Z10*W10
A11: =원데이터!A11 | B11: =원데이터!A11-DATE(YEAR(원데이터!A11),1,1)+1 | C11: =(원데이터!B11+원데이터!C11)/2 | D11: =0.6108*EXP(17.27*원데이터!B11/(원데이터!B11+237.3)) | E11: =0.6108*EXP(17.27*원데이터!C11/(원데이터!C11+237.3)) | F11: =(D11+E11)/2 | G11: =IF(원데이터!H11<>"",원데이터!H11/10,IF(원데이터!I11<>"",0.6108*EXP(17.27*원데이터!I11/(원데이터!I11+237.3)),원데이터!E11/100*F11)) | H11: =4098*(0.6108*EXP(17.27*C11/(C11+237.3)))/(C11+237.3)^2 | I11: =IF(원데이터!J11<>"",원데이터!J11/10,101.3*((293-0.0065*설정!$B$3)/293)^5.26) | J11: =0.000665*I11 | K11: =원데이터!G11*4.87/LN(67.8*설정!$B$4-5.42) | L11: =1+0.033*COS(2*PI()*B11/365) | M11: =0.409*SIN(2*PI()*B11/365-1.39) | N11: =ACOS(-TAN(RADIANS(설정!$B$2))*TAN(M11)) | O11: =(24*60/PI())*0.082*L11*(N11*SIN(RADIANS(설정!$B$2))*SIN(M11)+COS(RADIANS(설정!$B$2))*COS(M11)*SIN(N11)) | P11: =(0.75+0.00002*설정!$B$3)*O11 | Q11: =IF(원데이터!K11<>"",원데이터!K11,(0.25+0.5*원데이터!L11/(24/PI()*N11))*O11) | R11: =0.77*Q11 | S11: =0.000000004903*(((원데이터!B11+273.16)^4+(원데이터!C11+273.16)^4)/2)*(0.34-0.14*SQRT(G11))*(1.35*MIN(Q11/P11,1)-0.35) | T11: =R11-S11 | U11: =(0.408*H11*T11+J11*(900/(C11+273))*K11*(F11-G11))/(H11+J11*(1+0.34*K11)) | V11: =IF(원데이터!A11-설정!$B$16<0,"발아전",IF(원데이터!A11-설정!$B$16<설정!$B$17,"초기",IF(원데이터!A11-설정!$B$16<설정!$B$17+설정!$B$18,"발육",IF(원데이터!A11-설정!$B$16<설정!$B$17+설정!$B$18+설정!$B$19,"중기",IF(원데이터!A11-설정!$B$16<설정!$B$17+설정!$B$18+설정!$B$19+설정!$B$20,"후기","후기이후"))))) | W11: =IF(원데이터!A11-설정!$B$16<0,0,IF(원데이터!A11-설정!$B$16<설정!$B$17,설정!$B$33,IF(원데이터!A11-설정!$B$16<설정!$B$17+설정!$B$18,설정!$B$33+(설정!$B$34-설정!$B$33)*(원데이터!A11-설정!$B$16-설정!$B$17+1)/설정!$B$18,IF(원데이터!A11-설정!$B$16<설정!$B$17+설정!$B$18+설정!$B$19,설정!$B$34,IF(원데이터!A11-설정!$B$16<설정!$B$17+설정!$B$18+설정!$B$19+설정!$B$20,설정!$B$34+(설정!$B$35-설정!$B$34)*(원데이터!A11-설정!$B$16-설정!$B$17-설정!$B$18-설정!$B$19+1)/설정!$B$20,0))))) | X11: =0.108-0.0286*K11+0.0422*LN(설정!$B$5)+0.1434*LN(원데이터!E11)-0.000631*LN(설정!$B$5)^2*LN(원데이터!E11) | Y11: =원데이터!M11 | Z11: =X11*Y11 | AA11: =U11*W11 | AB11: =Z11*W11
A12: =원데이터!A12 | B12: =원데이터!A12-DATE(YEAR(원데이터!A12),1,1)+1 | C12: =(원데이터!B12+원데이터!C12)/2 | D12: =0.6108*EXP(17.27*원데이터!B12/(원데이터!B12+237.3)) | E12: =0.6108*EXP(17.27*원데이터!C12/(원데이터!C12+237.3)) | F12: =(D12+E12)/2 | G12: =IF(원데이터!H12<>"",원데이터!H12/10,IF(원데이터!I12<>"",0.6108*EXP(17.27*원데이터!I12/(원데이터!I12+237.3)),원데이터!E12/100*F12)) | H12: =4098*(0.6108*EXP(17.27*C12/(C12+237.3)))/(C12+237.3)^2 | I12: =IF(원데이터!J12<>"",원데이터!J12/10,101.3*((293-0.0065*설정!$B$3)/293)^5.26) | J12: =0.000665*I12 | K12: =원데이터!G12*4.87/LN(67.8*설정!$B$4-5.42) | L12: =1+0.033*COS(2*PI()*B12/365) | M12: =0.409*SIN(2*PI()*B12/365-1.39) | N12: =ACOS(-TAN(RADIANS(설정!$B$2))*TAN(M12)) | O12: =(24*60/PI())*0.082*L12*(N12*SIN(RADIANS(설정!$B$2))*SIN(M12)+COS(RADIANS(설정!$B$2))*COS(M12)*SIN(N12)) | P12: =(0.75+0.00002*설정!$B$3)*O12 | Q12: =IF(원데이터!K12<>"",원데이터!K12,(0.25+0.5*원데이터!L12/(24/PI()*N12))*O12) | R12: =0.77*Q12 | S12: =0.000000004903*(((원데이터!B12+273.16)^4+(원데이터!C12+273.16)^4)/2)*(0.34-0.14*SQRT(G12))*(1.35*MIN(Q12/P12,1)-0.35) | T12: =R12-S12 | U12: =(0.408*H12*T12+J12*(900/(C12+273))*K12*(F12-G12))/(H12+J12*(1+0.34*K12)) | V12: =IF(원데이터!A12-설정!$B$16<0,"발아전",IF(원데이터!A12-설정!$B$16<설정!$B$17,"초기",IF(원데이터!A12-설정!$B$16<설정!$B$17+설정!$B$18,"발육",IF(원데이터!A12-설정!$B$16<설정!$B$17+설정!$B$18+설정!$B$19,"중기",IF(원데이터!A12-설정!$B$16<설정!$B$17+설정!$B$18+설정!$B$19+설정!$B$20,"후기","후기이후"))))) | W12: =IF(원데이터!A12-설정!$B$16<0,0,IF(원데이터!A12-설정!$B$16<설정!$B$17,설정!$B$33,IF(원데이터!A12-설정!$B$16<설정!$B$17+설정!$B$18,설정!$B$33+(설정!$B$34-설정!$B$33)*(원데이터!A12-설정!$B$16-설정!$B$17+1)/설정!$B$18,IF(원데이터!A12-설정!$B$16<설정!$B$17+설정!$B$18+설정!$B$19,설정!$B$34,IF(원데이터!A12-설정!$B$16<설정!$B$17+설정!$B$18+설정!$B$19+설정!$B$20,설정!$B$34+(설정!$B$35-설정!$B$34)*(원데이터!A12-설정!$B$16-설정!$B$17-설정!$B$18-설정!$B$19+1)/설정!$B$20,0))))) | X12: =0.108-0.0286*K12+0.0422*LN(설정!$B$5)+0.1434*LN(원데이터!E12)-0.000631*LN(설정!$B$5)^2*LN(원데이터!E12) | Y12: =원데이터!M12 | Z12: =X12*Y12 | AA12: =U12*W12 | AB12: =Z12*W12
A13: =원데이터!A13 | B13: =원데이터!A13-DATE(YEAR(원데이터!A13),1,1)+1 | C13: =(원데이터!B13+원데이터!C13)/2 | D13: =0.6108*EXP(17.27*원데이터!B13/(원데이터!B13+237.3)) | E13: =0.6108*EXP(17.27*원데이터!C13/(원데이터!C13+237.3)) | F13: =(D13+E13)/2 | G13: =IF(원데이터!H13<>"",원데이터!H13/10,IF(원데이터!I13<>"",0.6108*EXP(17.27*원데이터!I13/(원데이터!I13+237.3)),원데이터!E13/100*F13)) | H13: =4098*(0.6108*EXP(17.27*C13/(C13+237.3)))/(C13+237.3)^2 | I13: =IF(원데이터!J13<>"",원데이터!J13/10,101.3*((293-0.0065*설정!$B$3)/293)^5.26) | J13: =0.000665*I13 | K13: =원데이터!G13*4.87/LN(67.8*설정!$B$4-5.42) | L13: =1+0.033*COS(2*PI()*B13/365) | M13: =0.409*SIN(2*PI()*B13/365-1.39) | N13: =ACOS(-TAN(RADIANS(설정!$B$2))*TAN(M13)) | O13: =(24*60/PI())*0.082*L13*(N13*SIN(RADIANS(설정!$B$2))*SIN(M13)+COS(RADIANS(설정!$B$2))*COS(M13)*SIN(N13)) | P13: =(0.75+0.00002*설정!$B$3)*O13 | Q13: =IF(원데이터!K13<>"",원데이터!K13,(0.25+0.5*원데이터!L13/(24/PI()*N13))*O13) | R13: =0.77*Q13 | S13: =0.000000004903*(((원데이터!B13+273.16)^4+(원데이터!C13+273.16)^4)/2)*(0.34-0.14*SQRT(G13))*(1.35*MIN(Q13/P13,1)-0.35) | T13: =R13-S13 | U13: =(0.408*H13*T13+J13*(900/(C13+273))*K13*(F13-G13))/(H13+J13*(1+0.34*K13)) | V13: =IF(원데이터!A13-설정!$B$16<0,"발아전",IF(원데이터!A13-설정!$B$16<설정!$B$17,"초기",IF(원데이터!A13-설정!$B$16<설정!$B$17+설정!$B$18,"발육",IF(원데이터!A13-설정!$B$16<설정!$B$17+설정!$B$18+설정!$B$19,"중기",IF(원데이터!A13-설정!$B$16<설정!$B$17+설정!$B$18+설정!$B$19+설정!$B$20,"후기","후기이후"))))) | W13: =IF(원데이터!A13-설정!$B$16<0,0,IF(원데이터!A13-설정!$B$16<설정!$B$17,설정!$B$33,IF(원데이터!A13-설정!$B$16<설정!$B$17+설정!$B$18,설정!$B$33+(설정!$B$34-설정!$B$33)*(원데이터!A13-설정!$B$16-설정!$B$17+1)/설정!$B$18,IF(원데이터!A13-설정!$B$16<설정!$B$17+설정!$B$18+설정!$B$19,설정!$B$34,IF(원데이터!A13-설정!$B$16<설정!$B$17+설정!$B$18+설정!$B$19+설정!$B$20,설정!$B$34+(설정!$B$35-설정!$B$34)*(원데이터!A13-설정!$B$16-설정!$B$17-설정!$B$18-설정!$B$19+1)/설정!$B$20,0))))) | X13: =0.108-0.0286*K13+0.0422*LN(설정!$B$5)+0.1434*LN(원데이터!E13)-0.000631*LN(설정!$B$5)^2*LN(원데이터!E13) | Y13: =원데이터!M13 | Z13: =X13*Y13 | AA13: =U13*W13 | AB13: =Z13*W13
... A257: =원데이터!A257 | B257: =원데이터!A257-DATE(YEAR(원데이터!A257),1,1)+1 | C257: =(원데이터!B257+원데이터!C257)/2 | D257: =0.6108*EXP(17.27*원데이터!B257/(원데이터!B257+237.3)) | E257: =0.6108*EXP(17.27*원데이터!C257/(원데이터!C257+237.3)) | F257: =(D257+E257)/2 | G257: =IF(원데이터!H257<>"",원데이터!H257/10,IF(원데이터!I257<>"",0.6108*EXP(17.27*원데이터!I257/(원데이터!I257+237.3)),원데이터!E257/100*F257)) | H257: =4098*(0.6108*EXP(17.27*C257/(C257+237.3)))/(C257+237.3)^2 | I257: =IF(원데이터!J257<>"",원데이터!J257/10,101.3*((293-0.0065*설정!$B$3)/293)^5.26) | J257: =0.000665*I257 | K257: =원데이터!G257*4.87/LN(67.8*설정!$B$4-5.42) | L257: =1+0.033*COS(2*PI()*B257/365) | M257: =0.409*SIN(2*PI()*B257/365-1.39) | N257: =ACOS(-TAN(RADIANS(설정!$B$2))*TAN(M257)) | O257: =(24*60/PI())*0.082*L257*(N257*SIN(RADIANS(설정!$B$2))*SIN(M257)+COS(RADIANS(설정!$B$2))*COS(M257)*SIN(N257)) | P257: =(0.75+0.00002*설정!$B$3)*O257 | Q257: =IF(원데이터!K257<>"",원데이터!K257,(0.25+0.5*원데이터!L257/(24/PI()*N257))*O257) | R257: =0.77*Q257 | S257: =0.000000004903*(((원데이터!B257+273.16)^4+(원데이터!C257+273.16)^4)/2)*(0.34-0.14*SQRT(G257))*(1.35*MIN(Q257/P257,1)-0.35) | T257: =R257-S257 | U257: =(0.408*H257*T257+J257*(900/(C257+273))*K257*(F257-G257))/(H257+J257*(1+0.34*K257)) | V257: =IF(원데이터!A257-설정!$B$16<0,"발아전",IF(원데이터!A257-설정!$B$16<설정!$B$17,"초기",IF(원데이터!A257-설정!$B$16<설정!$B$17+설정!$B$18,"발육",IF(원데이터!A257-설정!$B$16<설정!$B$17+설정!$B$18+설정!$B$19,"중기",IF(원데이터!A257-설정!$B$16<설정!$B$17+설정!$B$18+설정!$B$19+설정!$B$20,"후기","후기이후"))))) | W257: =IF(원데이터!A257-설정!$B$16<0,0,IF(원데이터!A257-설정!$B$16<설정!$B$17,설정!$B$33,IF(원데이터!A257-설정!$B$16<설정!$B$17+설정!$B$18,설정!$B$33+(설정!$B$34-설정!$B$33)*(원데이터!A257-설정!$B$16-설정!$B$17+1)/설정!$B$18,IF(원데이터!A257-설정!$B$16<설정!$B$17+설정!$B$18+설정!$B$19,설정!$B$34,IF(원데이터!A257-설정!$B$16<설정!$B$17+설정!$B$18+설정!$B$19+설정!$B$20,설정!$B$34+(설정!$B$35-설정!$B$34)*(원데이터!A257-설정!$B$16-설정!$B$17-설정!$B$18-설정!$B$19+1)/설정!$B$20,0))))) | X257: =0.108-0.0286*K257+0.0422*LN(설정!$B$5)+0.1434*LN(원데이터!E257)-0.000631*LN(설정!$B$5)^2*LN(원데이터!E257) | Y257: =원데이터!M257 | Z257: =X257*Y257 | AA257: =U257*W257 | AB257: =Z257*W257

Sheet 결과요약
A1: 지점 101 기준증발산량 결과요약 20260101~20260913
A3: ETo_PM 월합계 (mm) | B3: =SUM(계산과정!U2:U257)
A4: ETo_PM 일평균 (mm/d) | B4: =AVERAGE(계산과정!U2:U257)
A5: ETo_pan 월합계 (mm) | B5: =SUM(계산과정!Z2:Z257)
A6: ETo_pan 일평균 (mm/d) | B6: =AVERAGE(계산과정!Z2:Z257)
A7: 대형증발량 월합계 (mm) | B7: =SUM(계산과정!Y2:Y257)
A8: 두 방법 상관 r | B8: =IFERROR(CORREL(계산과정!U2:U257,계산과정!Z2:Z257),"—")
A9: 편향 ME (pan−PM, mm/d) | B9: =AVERAGE(계산과정!Z2:Z257)-AVERAGE(계산과정!U2:U257)
A10: RMSE (mm/d) | B10: =IFERROR(SQRT(SUMPRODUCT((계산과정!Z2:Z257-계산과정!U2:U257)^2)/256),"—")
A11: 월누적 차이 (pan/PM−1) | B11: =IFERROR(SUM(계산과정!Z2:Z257)/SUM(계산과정!U2:U257)-1,"—")
A12: ETc_PM (=Kc×ETo) 월합계 (mm) | B12: =SUM(계산과정!AA2:AA257)
A13: ETc_PM 일평균 (mm/d) | B13: =AVERAGE(계산과정!AA2:AA257)
A15: 물수지 요약 — 무관수(자연강우) 가정, FAO-56 Ch.8
A16: 기간 총강수 ΣP (mm) | B16: =SUM(물수지!F2:F257)
A17: 유효강수 (근권 흡수분, mm) | B17: =SUM(물수지!F2:F257)-SUM(물수지!H2:H257)
A18: 심층침투 ΣDP (mm) | B18: =SUM(물수지!H2:H257)
A19: 유효강수율 (%) | B19: =IFERROR((SUM(물수지!F2:F257)-SUM(물수지!H2:H257))/SUM(물수지!F2:F257)*100,"—")
A20: 관수 필요 발생 일수 | B20: =COUNTIF(물수지!M2:M257,"●")
A21: 필요 순관수량 ΣIn (mm) | B21: =SUM(물수지!N2:N257)
A22: 필요 총관수량 ΣIg (mm) | B22: =SUM(물수지!O2:O257)
A23: TAW (mm) | B23: =설정!$B$41
A24: RAW (mm) | B24: =설정!$B$42
A26: 일자 | B26: ETo_PM(mm) | C26: ETo_pan(mm) | D26: 대형증발량(mm) | E26: ETc_PM(mm) | F26: 강수(mm) | G26: Dr(mm) | H26: Ks | I26: 관수
A27: =계산과정!A2 | B27: =계산과정!U2 | C27: =계산과정!Z2 | D27: =계산과정!Y2 | E27: =계산과정!AA2 | F27: =물수지!F2 | G27: =물수지!L2 | H27: =물수지!J2 | I27: =물수지!M2
A28: =계산과정!A3 | B28: =계산과정!U3 | C28: =계산과정!Z3 | D28: =계산과정!Y3 | E28: =계산과정!AA3 | F28: =물수지!F3 | G28: =물수지!L3 | H28: =물수지!J3 | I28: =물수지!M3
A29: =계산과정!A4 | B29: =계산과정!U4 | C29: =계산과정!Z4 | D29: =계산과정!Y4 | E29: =계산과정!AA4 | F29: =물수지!F4 | G29: =물수지!L4 | H29: =물수지!J4 | I29: =물수지!M4
A30: =계산과정!A5 | B30: =계산과정!U5 | C30: =계산과정!Z5 | D30: =계산과정!Y5 | E30: =계산과정!AA5 | F30: =물수지!F5 | G30: =물수지!L5 | H30: =물수지!J5 | I30: =물수지!M5
A31: =계산과정!A6 | B31: =계산과정!U6 | C31: =계산과정!Z6 | D31: =계산과정!Y6 | E31: =계산과정!AA6 | F31: =물수지!F6 | G31: =물수지!L6 | H31: =물수지!J6 | I31: =물수지!M6
A32: =계산과정!A7 | B32: =계산과정!U7 | C32: =계산과정!Z7 | D32: =계산과정!Y7 | E32: =계산과정!AA7 | F32: =물수지!F7 | G32: =물수지!L7 | H32: =물수지!J7 | I32: =물수지!M7
A33: =계산과정!A8 | B33: =계산과정!U8 | C33: =계산과정!Z8 | D33: =계산과정!Y8 | E33: =계산과정!AA8 | F33: =물수지!F8 | G33: =물수지!L8 | H33: =물수지!J8 | I33: =물수지!M8
A34: =계산과정!A9 | B34: =계산과정!U9 | C34: =계산과정!Z9 | D34: =계산과정!Y9 | E34: =계산과정!AA9 | F34: =물수지!F9 | G34: =물수지!L9 | H34: =물수지!J9 | I34: =물수지!M9
A35: =계산과정!A10 | B35: =계산과정!U10 | C35: =계산과정!Z10 | D35: =계산과정!Y10 | E35: =계산과정!AA10 | F35: =물수지!F10 | G35: =물수지!L10 | H35: =물수지!J10 | I35: =물수지!M10
A36: =계산과정!A11 | B36: =계산과정!U11 | C36: =계산과정!Z11 | D36: =계산과정!Y11 | E36: =계산과정!AA11 | F36: =물수지!F11 | G36: =물수지!L11 | H36: =물수지!J11 | I36: =물수지!M11
A37: =계산과정!A12 | B37: =계산과정!U12 | C37: =계산과정!Z12 | D37: =계산과정!Y12 | E37: =계산과정!AA12 | F37: =물수지!F12 | G37: =물수지!L12 | H37: =물수지!J12 | I37: =물수지!M12
A38: =계산과정!A13 | B38: =계산과정!U13 | C38: =계산과정!Z13 | D38: =계산과정!Y13 | E38: =계산과정!AA13 | F38: =물수지!F13 | G38: =물수지!L13 | H38: =물수지!J13 | I38: =물수지!M13
... A282: =계산과정!A257 | B282: =계산과정!U257 | C282: =계산과정!Z257 | D282: =계산과정!Y257 | E282: =계산과정!AA257 | F282: =물수지!F257 | G282: =물수지!L257 | H282: =물수지!J257 | I282: =물수지!M257

Sheet 물수지
A1: 일자 | B1: 생육단계 | C1: Kc | D1: ETo (mm) | E1: ETc (mm) | F1: 강수P (mm) | G1: Dr,i-1 (mm) | H1: DP (mm) | I1: Dr비후 (mm) | J1: Ks | K1: ETc_adj (mm) | L1: Dr,i (mm) | M1: 관수 필요 | N1: 필요 순관수량 In (mm) | O1: 필요 총관수량 Ig (mm)
A2: =계산과정!A2 | B2: =계산과정!V2 | C2: =계산과정!W2 | D2: =계산과정!U2 | E2: =D2*C2 | F2: =원데이터!N2 | G2: =설정!$B$43 | H2: =MAX(F2-G2, 0) | I2: =MAX(G2-F2, 0) | J2: =IF(I2<=설정!$B$42, 1, (설정!$B$41-I2)/(설정!$B$41-설정!$B$42)) | K2: =J2*E2 | L2: =MIN(I2+K2, 설정!$B$41) | M2: =IF(L2>=설정!$B$42,"●","") | N2: =IF(M2="●",L2,0) | O2: =IF(N2>0,N2/설정!$B$44,0)
A3: =계산과정!A3 | B3: =계산과정!V3 | C3: =계산과정!W3 | D3: =계산과정!U3 | E3: =D3*C3 | F3: =원데이터!N3 | G3: =L2 | H3: =MAX(F3-G3, 0) | I3: =MAX(G3-F3, 0) | J3: =IF(I3<=설정!$B$42, 1, (설정!$B$41-I3)/(설정!$B$41-설정!$B$42)) | K3: =J3*E3 | L3: =MIN(I3+K3, 설정!$B$41) | M3: =IF(L3>=설정!$B$42,"●","") | N3: =IF(M3="●",L3,0) | O3: =IF(N3>0,N3/설정!$B$44,0)
A4: =계산과정!A4 | B4: =계산과정!V4 | C4: =계산과정!W4 | D4: =계산과정!U4 | E4: =D4*C4 | F4: =원데이터!N4 | G4: =L3 | H4: =MAX(F4-G4, 0) | I4: =MAX(G4-F4, 0) | J4: =IF(I4<=설정!$B$42, 1, (설정!$B$41-I4)/(설정!$B$41-설정!$B$42)) | K4: =J4*E4 | L4: =MIN(I4+K4, 설정!$B$41) | M4: =IF(L4>=설정!$B$42,"●","") | N4: =IF(M4="●",L4,0) | O4: =IF(N4>0,N4/설정!$B$44,0)
A5: =계산과정!A5 | B5: =계산과정!V5 | C5: =계산과정!W5 | D5: =계산과정!U5 | E5: =D5*C5 | F5: =원데이터!N5 | G5: =L4 | H5: =MAX(F5-G5, 0) | I5: =MAX(G5-F5, 0) | J5: =IF(I5<=설정!$B$42, 1, (설정!$B$41-I5)/(설정!$B$41-설정!$B$42)) | K5: =J5*E5 | L5: =MIN(I5+K5, 설정!$B$41) | M5: =IF(L5>=설정!$B$42,"●","") | N5: =IF(M5="●",L5,0) | O5: =IF(N5>0,N5/설정!$B$44,0)
A6: =계산과정!A6 | B6: =계산과정!V6 | C6: =계산과정!W6 | D6: =계산과정!U6 | E6: =D6*C6 | F6: =원데이터!N6 | G6: =L5 | H6: =MAX(F6-G6, 0) | I6: =MAX(G6-F6, 0) | J6: =IF(I6<=설정!$B$42, 1, (설정!$B$41-I6)/(설정!$B$41-설정!$B$42)) | K6: =J6*E6 | L6: =MIN(I6+K6, 설정!$B$41) | M6: =IF(L6>=설정!$B$42,"●","") | N6: =IF(M6="●",L6,0) | O6: =IF(N6>0,N6/설정!$B$44,0)
A7: =계산과정!A7 | B7: =계산과정!V7 | C7: =계산과정!W7 | D7: =계산과정!U7 | E7: =D7*C7 | F7: =원데이터!N7 | G7: =L6 | H7: =MAX(F7-G7, 0) | I7: =MAX(G7-F7, 0) | J7: =IF(I7<=설정!$B$42, 1, (설정!$B$41-I7)/(설정!$B$41-설정!$B$42)) | K7: =J7*E7 | L7: =MIN(I7+K7, 설정!$B$41) | M7: =IF(L7>=설정!$B$42,"●","") | N7: =IF(M7="●",L7,0) | O7: =IF(N7>0,N7/설정!$B$44,0)
A8: =계산과정!A8 | B8: =계산과정!V8 | C8: =계산과정!W8 | D8: =계산과정!U8 | E8: =D8*C8 | F8: =원데이터!N8 | G8: =L7 | H8: =MAX(F8-G8, 0) | I8: =MAX(G8-F8, 0) | J8: =IF(I8<=설정!$B$42, 1, (설정!$B$41-I8)/(설정!$B$41-설정!$B$42)) | K8: =J8*E8 | L8: =MIN(I8+K8, 설정!$B$41) | M8: =IF(L8>=설정!$B$42,"●","") | N8: =IF(M8="●",L8,0) | O8: =IF(N8>0,N8/설정!$B$44,0)
A9: =계산과정!A9 | B9: =계산과정!V9 | C9: =계산과정!W9 | D9: =계산과정!U9 | E9: =D9*C9 | F9: =원데이터!N9 | G9: =L8 | H9: =MAX(F9-G9, 0) | I9: =MAX(G9-F9, 0) | J9: =IF(I9<=설정!$B$42, 1, (설정!$B$41-I9)/(설정!$B$41-설정!$B$42)) | K9: =J9*E9 | L9: =MIN(I9+K9, 설정!$B$41) | M9: =IF(L9>=설정!$B$42,"●","") | N9: =IF(M9="●",L9,0) | O9: =IF(N9>0,N9/설정!$B$44,0)
A10: =계산과정!A10 | B10: =계산과정!V10 | C10: =계산과정!W10 | D10: =계산과정!U10 | E10: =D10*C10 | F10: =원데이터!N10 | G10: =L9 | H10: =MAX(F10-G10, 0) | I10: =MAX(G10-F10, 0) | J10: =IF(I10<=설정!$B$42, 1, (설정!$B$41-I10)/(설정!$B$41-설정!$B$42)) | K10: =J10*E10 | L10: =MIN(I10+K10, 설정!$B$41) | M10: =IF(L10>=설정!$B$42,"●","") | N10: =IF(M10="●",L10,0) | O10: =IF(N10>0,N10/설정!$B$44,0)
A11: =계산과정!A11 | B11: =계산과정!V11 | C11: =계산과정!W11 | D11: =계산과정!U11 | E11: =D11*C11 | F11: =원데이터!N11 | G11: =L10 | H11: =MAX(F11-G11, 0) | I11: =MAX(G11-F11, 0) | J11: =IF(I11<=설정!$B$42, 1, (설정!$B$41-I11)/(설정!$B$41-설정!$B$42)) | K11: =J11*E11 | L11: =MIN(I11+K11, 설정!$B$41) | M11: =IF(L11>=설정!$B$42,"●","") | N11: =IF(M11="●",L11,0) | O11: =IF(N11>0,N11/설정!$B$44,0)
A12: =계산과정!A12 | B12: =계산과정!V12 | C12: =계산과정!W12 | D12: =계산과정!U12 | E12: =D12*C12 | F12: =원데이터!N12 | G12: =L11 | H12: =MAX(F12-G12, 0) | I12: =MAX(G12-F12, 0) | J12: =IF(I12<=설정!$B$42, 1, (설정!$B$41-I12)/(설정!$B$41-설정!$B$42)) | K12: =J12*E12 | L12: =MIN(I12+K12, 설정!$B$41) | M12: =IF(L12>=설정!$B$42,"●","") | N12: =IF(M12="●",L12,0) | O12: =IF(N12>0,N12/설정!$B$44,0)
A13: =계산과정!A13 | B13: =계산과정!V13 | C13: =계산과정!W13 | D13: =계산과정!U13 | E13: =D13*C13 | F13: =원데이터!N13 | G13: =L12 | H13: =MAX(F13-G13, 0) | I13: =MAX(G13-F13, 0) | J13: =IF(I13<=설정!$B$42, 1, (설정!$B$41-I13)/(설정!$B$41-설정!$B$42)) | K13: =J13*E13 | L13: =MIN(I13+K13, 설정!$B$41) | M13: =IF(L13>=설정!$B$42,"●","") | N13: =IF(M13="●",L13,0) | O13: =IF(N13>0,N13/설정!$B$44,0)
A14: =계산과정!A14 | B14: =계산과정!V14 | C14: =계산과정!W14 | D14: =계산과정!U14 | E14: =D14*C14 | F14: =원데이터!N14 | G14: =L13 | H14: =MAX(F14-G14, 0) | I14: =MAX(G14-F14, 0) | J14: =IF(I14<=설정!$B$42, 1, (설정!$B$41-I14)/(설정!$B$41-설정!$B$42)) | K14: =J14*E14 | L14: =MIN(I14+K14, 설정!$B$41) | M14: =IF(L14>=설정!$B$42,"●","") | N14: =IF(M14="●",L14,0) | O14: =IF(N14>0,N14/설정!$B$44,0)
... A257: =계산과정!A257 | B257: =계산과정!V257 | C257: =계산과정!W257 | D257: =계산과정!U257 | E257: =D257*C257 | F257: =원데이터!N257 | G257: =L256 | H257: =MAX(F257-G257, 0) | I257: =MAX(G257-F257, 0) | J257: =IF(I257<=설정!$B$42, 1, (설정!$B$41-I257)/(설정!$B$41-설정!$B$42)) | K257: =J257*E257 | L257: =MIN(I257+K257, 설정!$B$41) | M257: =IF(L257>=설정!$B$42,"●","") | N257: =IF(M257="●",L257,0) | O257: =IF(N257>0,N257/설정!$B$44,0)

Sheet 계산근거
A1: ETo 산출 근거 (FAO-56)
A2: 기준 | B2: Allen et al., FAO Irrigation & Drainage Paper 56 (1998)
A3: 원데이터 | B3: 기상청 ASOS 일자료(공공데이터포털 getWthrDataList) — 공개 OpenAPI만 사용
A4: es | B4: 포화수증기압 (e°(Tmax)+e°(Tmin))/2, e°(T)=0.6108·EXP(17.27·T/(T+237.3)) [식11]
A5: ea | B5: 실제수증기압. 우선순위: 측정증기압(avgPv÷10) → 이슬점 e°(avgTd) → 상대습도(RH/100·es)
A6: Δ | B6: 포화수증기압곡선 기울기 4098·e°(T)/(T+237.3)² [식13]
A7: P, γ | B7: P=현지기압(avgPa÷10) 또는 고도식, γ=0.000665·P [식7,8]
A8: u₂ | B8: 2m 풍속 u_z·4.87/LN(67.8·z−5.42), z=풍속계높이 [식47]
A9: Ra | B9: 천문일사: 위도·연중일(DOY)로 산정 (dr·δ·ωs 경유) [식21]
A10: Rso | B10: 청천일사 (0.75+2e-5·고도)·Ra [식37]
A11: Rs | B11: 일사: 측정 합계일사(sumGsr) 우선, 결측 시 일조기반 Ångström (0.25+0.50·n/N)·Ra [식35]
A12: Rn | B12: 순복사 Rns−Rnl, Rns=0.77·Rs, Rnl=σ·((Tmax⁴+Tmin⁴)/2)·(0.34−0.14·√ea)·(1.35·Rs/Rso−0.35) [식38~40]
A13: ETo_PM | B13: 기준증발산량(PM). 분자 0.408·Δ·Rn + γ·900/(T+273)·u₂·(es−ea), 분모 Δ + γ·(1+0.34·u₂) [식6, G=0]
... A20: ETc | B20: 일별 ETc = 일별 Kc × ETo. 계산과정 시트에서 매일 자동 산출. Kc_pan 방식은 참고용(같은 일별 Kc를 ETo_pan에 곱함).
A21: 물수지 근거 (FAO-56 Ch.8)
A22: TAW [식82] | B22: 총유효수분 TAW = 1000·(θFC−θWP)·Zr (mm). θFC/θWP는 FAO-56 Table 19, Zr은 Table 22 기준값.
A23: RAW [식83] | B23: 쉽게이용가능수분 RAW = p·TAW (mm). Dr이 RAW에 도달하면 작물이 스트레스를 받기 시작. p는 Table 22 기준값.
A24: Ks [식84] | B24: 수분스트레스계수. Dr≤RAW이면 Ks=1(무스트레스). Dr>RAW이면 Ks=(TAW−Dr)/(TAW−RAW), 0~1 범위.
A25: Dr [식85] | B25: 일별 근권 고갈량. Dr,i = Dr,i-1 − P + ETc,adj + DP. 범위: 0 ≤ Dr ≤ TAW.
A26: DP [식88] | B26: 심층침투. DP = max(P − Dr,i-1, 0). 강수가 현재 고갈량보다 많으면 근권을 넘쳐 아래로 배수.
A27: ETc_adj [식81] | B27: 스트레스 보정 후 증발산. ETc_adj = Ks · Kc · ETo. Ks<1이면 실제 소비량이 잠재 ETc보다 줄어듦.
A28: 관수필요 판정 | B28: Dr,i ≥ RAW이면 관수 필요(●). 무관수(자연강우만) 가정이므로 ● 이후에도 Dr 리셋 없이 계속 누적됨. 실측 관수 데이터는 다음 버전에서 식(85)에 직접 반영 예정.
A29: 필요 순관수량 In | B29: net irrigation depth. 관수필요(●) 시점의 Dr 값. 근권을 포장용수량(Dr=0)까지 보충하는 데 필요한 순수량(mm). 이론적 필요량이며 실측 관수량이 아님.
A30: 필요 총관수량 Ig | B30: gross irrigation depth. In을 관수효율 Ea로 나눈 값(Ig = In/Ea). 손실(미도달·증발 등)을 포함한 실제 공급 필요량. 점적관수 Ea=0.95 기준.
A31: 계산과정 시트 | B31: 모든 셀이 라이브 수식. 셀 클릭 시 수식 확인 가능. 설정값 변경 시 자동 재계산됨.
A32: 물수지 시트 | B32: 라이브 수식. 설정의 토양 파라미터(θFC/θWP/Zr/p) 변경 시 전체 자동 재계산됨.
A33: 주의 | B33: 일사·대형증발량은 지점별 관측 여부 상이. 물수지는 RO(지표유출)=0, CR(모관상승)=0, 실측 관수량=0(무관수 가정)으로 단순화.
